<?xml version="1.0"?>
<robot name="warehouse_robot">

  <!-- ======================= LINKS ======================= -->

  <!-- Base Link (Chassis) -->
  <link name="base_link">
    <visual>
      <geometry>
        <box size="0.4 0.3 0.1"/>
      </geometry>
      <origin xyz="0 0 0.05" rpy="0 0 0"/>
      <material name="blue">
        <color rgba="0.0 0.0 0.8 1.0"/>
      </material>
    </visual>
    <collision>
      <geometry>
        <box size="0.4 0.3 0.1"/>
      </geometry>
      <origin xyz="0 0 0.05" rpy="0 0 0"/>
    </collision>
    <inertial>
      <mass value="5.0"/>
      <origin xyz="0 0 0.05" rpy="0 0 0"/>
      <inertia ixx="0.04" ixy="0.0" ixz="0.0" iyy="0.08" iyz="0.0" izz="0.10"/>
    </inertial>
  </link>

  <!-- Left Wheel Link -->
  <link name="left_wheel_link">
    <visual>
      <geometry>
        <cylinder radius="0.05" length="0.04"/>
      </geometry>
      <origin xyz="0 0 0" rpy="1.5707 0 0"/> <!-- Rotate cylinder to be upright -->
      <material name="white">
        <color rgba="1.0 1.0 1.0 1.0"/>
      </material>
    </visual>
    <collision>
      <geometry>
        <cylinder radius="0.05" length="0.04"/>
      </geometry>
      <origin xyz="0 0 0" rpy="1.5707 0 0"/>
    </collision>
    <inertial>
      <mass value="0.5"/>
      <inertia ixx="0.001" ixy="0.0" ixz="0.0" iyy="0.001" iyz="0.0" izz="0.001"/>
    </inertial>
  </link>

  <!-- Right Wheel Link -->
  <link name="right_wheel_link">
    <visual>
      <geometry>
        <cylinder radius="0.05" length="0.04"/>
      </geometry>
      <origin xyz="0 0 0" rpy="1.5707 0 0"/>
      <material name="white"/>
    </visual>
    <collision>
      <geometry>
        <cylinder radius="0.05" length="0.04"/>
      </geometry>
      <origin xyz="0 0 0" rpy="1.5707 0 0"/>
    </collision>
    <inertial>
      <mass value="0.5"/>
      <inertia ixx="0.001" ixy="0.0" ixz="0.0" iyy="0.001" iyz="0.0" izz="0.001"/>
    </inertial>
  </link>

  <!-- Caster Wheel Link (for stability) -->
  <link name="caster_wheel_link">
    <visual>
      <geometry>
        <sphere radius="0.03"/>
      </geometry>
      <origin xyz="0 0 0" rpy="0 0 0"/>
      <material name="grey">
        <color rgba="0.5 0.5 0.5 1.0"/>
      </material>
    </visual>
    <collision>
      <geometry>
        <sphere radius="0.03"/>
      </geometry>
      <origin xyz="0 0 0" rpy="0 0 0"/>
    </collision>
    <inertial>
      <mass value="0.2"/>
      <inertia ixx="0.0001" ixy="0.0" ixz="0.0" iyy="0.0001" iyz="0.0" izz="0.0001"/>
    </inertial>
  </link>

  <!-- ======================= JOINTS ======================= -->

  <!-- Joint connecting Base to Left Wheel -->
  <joint name="base_to_left_wheel_joint" type="continuous">
    <parent link="base_link"/>
    <child link="left_wheel_link"/>
    <origin xyz="0.0 0.17 0.0" rpy="0 0 0"/>
    <axis xyz="0 1 0"/>
  </joint>

  <!-- Joint connecting Base to Right Wheel -->
  <joint name="base_to_right_wheel_joint" type="continuous">
    <parent link="base_link"/>
    <child link="right_wheel_link"/>
    <origin xyz="0.0 -0.17 0.0" rpy="0 0 0"/>
    <axis xyz="0 1 0"/>
  </joint>

  <!-- Joint connecting Base to Caster Wheel -->
  <joint name="base_to_caster_joint" type="fixed">
    <parent link="base_link"/>
    <child link="caster_wheel_link"/>
    <origin xyz="-0.15 0 -0.02" rpy="0 0 0"/>
  </joint>

  <!-- ======================= GAZEBO PLUGIN ======================= -->
  <gazebo>
    <plugin
      filename="libgz-sim-diff-drive-system"
      name="gz::sim::systems::DiffDrive">
      <left_joint>base_to_left_wheel_joint</left_joint>
      <right_joint>base_to_right_wheel_joint</right_joint>
      <chassis_link>base_link</chassis_link>
      <topic>/cmd_vel</topic>
      <odom_topic>/odom</odom_topic>
      <odom_frame>odom</odom_frame>
      <robot_base_frame>base_link</robot_base_frame>
      <publish_odom>true</publish_odom>
    </plugin>
  </gazebo>

</robot>
